Workbook

Sheet Read me
A1: Teradyne — primary research regression
A2: Test-house revenue growth against assembly revenue growth, Taiwan
A4: Purpose
A5: Tests whether the relationship between independent test-house revenue growth and assembly revenue
A6: growth changed after the AI ramp. Two regressions are fitted, one per regime, and the difference in
A7: intercepts is tested formally. Every figure below recalculates from the raw revenue on the Data tab.
A9: Source
A10: Taiwan Stock Exchange Market Observation Post System (MOPS), statutory monthly revenue filings,
A11: January 2019 to June 2026. Test houses: King Yuan Electronics (2449), Sigurd Microelectronics (6257),
A12: Ardentec (3264), summed. Assembly benchmark: ASE Technology Holding (3711).
A13: Collected using 1. ATE Primary Research.py, which accompanies this workbook.
A15: Method
... A35: autocorrelated; the p-value below uses classical standard errors and is the conservative reading.

Sheet Data
A1: Month | B1: Test houses (NT$'000) | C1: Assembly ASE (NT$'000) | D1: Test y/y (%) | E1: Assembly y/y (%) | F1: Cal. month | G1: Include? | H1: Regime (0/1) | I1: In regime 1 | J1: In regime 2 | K1: x | regime 1 | L1: y | regime 1 | M1: x | regime 2 | N1: y | regime 2 | O1: Excluded because
A2: 2019-01 | B2: 3037157 | C2: 33055773 | F2: =VALUE(MID(A2,6,2)) -> 1 | G2: =IF(AND(ROW()>=14,F2<>2,F2<>3),1,0) -> 0 | H2: =IF(LEFT(A2,4)*1>=2025,1,0) -> 0 | I2: =IF(AND(G2=1,H2=0),1,0) -> 0 | J2: =IF(AND(G2=1,H2=1),1,0) -> 0 | K2: =IF(I2=1,E2,0) -> 0 | L2: =IF(I2=1,D2,0) -> 0 | M2: =IF(J2=1,E2,0) -> 0 | N2: =IF(J2=1,D2,0) -> 0 | O2: =IF(G2=1,"",IF(ROW()<14,"No prior-year base for a y/y comparison","Lunar New Year moves between Feb and Mar, so the y/y comparison is unreliable")) -> No prior-year base for a y/y comparison
A3: 2019-02 | B3: 2710409 | C3: 26239644 | F3: =VALUE(MID(A3,6,2)) -> 2 | G3: =IF(AND(ROW()>=14,F3<>2,F3<>3),1,0) -> 0 | H3: =IF(LEFT(A3,4)*1>=2025,1,0) -> 0 | I3: =IF(AND(G3=1,H3=0),1,0) -> 0 | J3: =IF(AND(G3=1,H3=1),1,0) -> 0 | K3: =IF(I3=1,E3,0) -> 0 | L3: =IF(I3=1,D3,0) -> 0 | M3: =IF(J3=1,E3,0) -> 0 | N3: =IF(J3=1,D3,0) -> 0 | O3: =IF(G3=1,"",IF(ROW()<14,"No prior-year base for a y/y comparison","Lunar New Year moves between Feb and Mar, so the y/y comparison is unreliable")) -> No prior-year base for a y/y comparison
A4: 2019-03 | B4: 3306280 | C4: 29566029 | F4: =VALUE(MID(A4,6,2)) -> 3 | G4: =IF(AND(ROW()>=14,F4<>2,F4<>3),1,0) -> 0 | H4: =IF(LEFT(A4,4)*1>=2025,1,0) -> 0 | I4: =IF(AND(G4=1,H4=0),1,0) -> 0 | J4: =IF(AND(G4=1,H4=1),1,0) -> 0 | K4: =IF(I4=1,E4,0) -> 0 | L4: =IF(I4=1,D4,0) -> 0 | M4: =IF(J4=1,E4,0) -> 0 | N4: =IF(J4=1,D4,0) -> 0 | O4: =IF(G4=1,"",IF(ROW()<14,"No prior-year base for a y/y comparison","Lunar New Year moves between Feb and Mar, so the y/y comparison is unreliable")) -> No prior-year base for a y/y comparison
A5: 2019-04 | B5: 3221293 | C5: 29051464 | F5: =VALUE(MID(A5,6,2)) -> 4 | G5: =IF(AND(ROW()>=14,F5<>2,F5<>3),1,0) -> 0 | H5: =IF(LEFT(A5,4)*1>=2025,1,0) -> 0 | I5: =IF(AND(G5=1,H5=0),1,0) -> 0 | J5: =IF(AND(G5=1,H5=1),1,0) -> 0 | K5: =IF(I5=1,E5,0) -> 0 | L5: =IF(I5=1,D5,0) -> 0 | M5: =IF(J5=1,E5,0) -> 0 | N5: =IF(J5=1,D5,0) -> 0 | O5: =IF(G5=1,"",IF(ROW()<14,"No prior-year base for a y/y comparison","Lunar New Year moves between Feb and Mar, so the y/y comparison is unreliable")) -> No prior-year base for a y/y comparison
A6: 2019-05 | B6: 3477654 | C6: 30118129 | F6: =VALUE(MID(A6,6,2)) -> 5 | G6: =IF(AND(ROW()>=14,F6<>2,F6<>3),1,0) -> 0 | H6: =IF(LEFT(A6,4)*1>=2025,1,0) -> 0 | I6: =IF(AND(G6=1,H6=0),1,0) -> 0 | J6: =IF(AND(G6=1,H6=1),1,0) -> 0 | K6: =IF(I6=1,E6,0) -> 0 | L6: =IF(I6=1,D6,0) -> 0 | M6: =IF(J6=1,E6,0) -> 0 | N6: =IF(J6=1,D6,0) -> 0 | O6: =IF(G6=1,"",IF(ROW()<14,"No prior-year base for a y/y comparison","Lunar New Year moves between Feb and Mar, so the y/y comparison is unreliable")) -> No prior-year base for a y/y comparison
A7: 2019-06 | B7: 3586758 | C7: 31571316 | F7: =VALUE(MID(A7,6,2)) -> 6 | G7: =IF(AND(ROW()>=14,F7<>2,F7<>3),1,0) -> 0 | H7: =IF(LEFT(A7,4)*1>=2025,1,0) -> 0 | I7: =IF(AND(G7=1,H7=0),1,0) -> 0 | J7: =IF(AND(G7=1,H7=1),1,0) -> 0 | K7: =IF(I7=1,E7,0) -> 0 | L7: =IF(I7=1,D7,0) -> 0 | M7: =IF(J7=1,E7,0) -> 0 | N7: =IF(J7=1,D7,0) -> 0 | O7: =IF(G7=1,"",IF(ROW()<14,"No prior-year base for a y/y comparison","Lunar New Year moves between Feb and Mar, so the y/y comparison is unreliable")) -> No prior-year base for a y/y comparison
A8: 2019-07 | B8: 3896593 | C8: 36376356 | F8: =VALUE(MID(A8,6,2)) -> 7 | G8: =IF(AND(ROW()>=14,F8<>2,F8<>3),1,0) -> 0 | H8: =IF(LEFT(A8,4)*1>=2025,1,0) -> 0 | I8: =IF(AND(G8=1,H8=0),1,0) -> 0 | J8: =IF(AND(G8=1,H8=1),1,0) -> 0 | K8: =IF(I8=1,E8,0) -> 0 | L8: =IF(I8=1,D8,0) -> 0 | M8: =IF(J8=1,E8,0) -> 0 | N8: =IF(J8=1,D8,0) -> 0 | O8: =IF(G8=1,"",IF(ROW()<14,"No prior-year base for a y/y comparison","Lunar New Year moves between Feb and Mar, so the y/y comparison is unreliable")) -> No prior-year base for a y/y comparison
A9: 2019-08 | B9: 3991763 | C9: 40039028 | F9: =VALUE(MID(A9,6,2)) -> 8 | G9: =IF(AND(ROW()>=14,F9<>2,F9<>3),1,0) -> 0 | H9: =IF(LEFT(A9,4)*1>=2025,1,0) -> 0 | I9: =IF(AND(G9=1,H9=0),1,0) -> 0 | J9: =IF(AND(G9=1,H9=1),1,0) -> 0 | K9: =IF(I9=1,E9,0) -> 0 | L9: =IF(I9=1,D9,0) -> 0 | M9: =IF(J9=1,E9,0) -> 0 | N9: =IF(J9=1,D9,0) -> 0 | O9: =IF(G9=1,"",IF(ROW()<14,"No prior-year base for a y/y comparison","Lunar New Year moves between Feb and Mar, so the y/y comparison is unreliable")) -> No prior-year base for a y/y comparison
A10: 2019-09 | B10: 3838773 | C10: 41141924 | F10: =VALUE(MID(A10,6,2)) -> 9 | G10: =IF(AND(ROW()>=14,F10<>2,F10<>3),1,0) -> 0 | H10: =IF(LEFT(A10,4)*1>=2025,1,0) -> 0 | I10: =IF(AND(G10=1,H10=0),1,0) -> 0 | J10: =IF(AND(G10=1,H10=1),1,0) -> 0 | K10: =IF(I10=1,E10,0) -> 0 | L10: =IF(I10=1,D10,0) -> 0 | M10: =IF(J10=1,E10,0) -> 0 | N10: =IF(J10=1,D10,0) -> 0 | O10: =IF(G10=1,"",IF(ROW()<14,"No prior-year base for a y/y comparison","Lunar New Year moves between Feb and Mar, so the y/y comparison is unreliable")) -> No prior-year base for a y/y comparison
A11: 2019-10 | B11: 4564259 | C11: 38784584 | F11: =VALUE(MID(A11,6,2)) -> 10 | G11: =IF(AND(ROW()>=14,F11<>2,F11<>3),1,0) -> 0 | H11: =IF(LEFT(A11,4)*1>=2025,1,0) -> 0 | I11: =IF(AND(G11=1,H11=0),1,0) -> 0 | J11: =IF(AND(G11=1,H11=1),1,0) -> 0 | K11: =IF(I11=1,E11,0) -> 0 | L11: =IF(I11=1,D11,0) -> 0 | M11: =IF(J11=1,E11,0) -> 0 | N11: =IF(J11=1,D11,0) -> 0 | O11: =IF(G11=1,"",IF(ROW()<14,"No prior-year base for a y/y comparison","Lunar New Year moves between Feb and Mar, so the y/y comparison is unreliable")) -> No prior-year base for a y/y comparison
A12: 2019-11 | B12: 3936959 | C12: 38456363 | F12: =VALUE(MID(A12,6,2)) -> 11 | G12: =IF(AND(ROW()>=14,F12<>2,F12<>3),1,0) -> 0 | H12: =IF(LEFT(A12,4)*1>=2025,1,0) -> 0 | I12: =IF(AND(G12=1,H12=0),1,0) -> 0 | J12: =IF(AND(G12=1,H12=1),1,0) -> 0 | K12: =IF(I12=1,E12,0) -> 0 | L12: =IF(I12=1,D12,0) -> 0 | M12: =IF(J12=1,E12,0) -> 0 | N12: =IF(J12=1,D12,0) -> 0 | O12: =IF(G12=1,"",IF(ROW()<14,"No prior-year base for a y/y comparison","Lunar New Year moves between Feb and Mar, so the y/y comparison is unreliable")) -> No prior-year base for a y/y comparison
A13: 2019-12 | B13: 4068297 | C13: 38781574 | F13: =VALUE(MID(A13,6,2)) -> 12 | G13: =IF(AND(ROW()>=14,F13<>2,F13<>3),1,0) -> 0 | H13: =IF(LEFT(A13,4)*1>=2025,1,0) -> 0 | I13: =IF(AND(G13=1,H13=0),1,0) -> 0 | J13: =IF(AND(G13=1,H13=1),1,0) -> 0 | K13: =IF(I13=1,E13,0) -> 0 | L13: =IF(I13=1,D13,0) -> 0 | M13: =IF(J13=1,E13,0) -> 0 | N13: =IF(J13=1,D13,0) -> 0 | O13: =IF(G13=1,"",IF(ROW()<14,"No prior-year base for a y/y comparison","Lunar New Year moves between Feb and Mar, so the y/y comparison is unreliable")) -> No prior-year base for a y/y comparison
A14: 2020-01 | B14: 3794224 | C14: 31337455 | D14: =(B14/B2-1)*100 -> 24.926831 | E14: =(C14/C2-1)*100 -> -5.1982387 | F14: =VALUE(MID(A14,6,2)) -> 1 | G14: =IF(AND(ROW()>=14,F14<>2,F14<>3),1,0) -> 1 | H14: =IF(LEFT(A14,4)*1>=2025,1,0) -> 0 | I14: =IF(AND(G14=1,H14=0),1,0) -> 1 | J14: =IF(AND(G14=1,H14=1),1,0) -> 0 | K14: =IF(I14=1,E14,0) -> -5.1982387 | L14: =IF(I14=1,D14,0) -> 24.926831 | M14: =IF(J14=1,E14,0) -> 0 | N14: =IF(J14=1,D14,0) -> 0 | O14: =IF(G14=1,"",IF(ROW()<14,"No prior-year base for a y/y comparison","Lunar New Year moves between Feb and Mar, so the y/y comparison is unreliable"))
A15: 2020-02 | B15: 3770183 | C15: 28135554 | D15: =(B15/B3-1)*100 -> 39.100151 | E15: =(C15/C3-1)*100 -> 7.2253648 | F15: =VALUE(MID(A15,6,2)) -> 2 | G15: =IF(AND(ROW()>=14,F15<>2,F15<>3),1,0) -> 0 | H15: =IF(LEFT(A15,4)*1>=2025,1,0) -> 0 | I15: =IF(AND(G15=1,H15=0),1,0) -> 0 | J15: =IF(AND(G15=1,H15=1),1,0) -> 0 | K15: =IF(I15=1,E15,0) -> 0 | L15: =IF(I15=1,D15,0) -> 0 | M15: =IF(J15=1,E15,0) -> 0 | N15: =IF(J15=1,D15,0) -> 0 | O15: =IF(G15=1,"",IF(ROW()<14,"No prior-year base for a y/y comparison","Lunar New Year moves between Feb and Mar, so the y/y comparison is unreliable")) -> Lunar New Year moves between Feb and Mar, so the y/y comparison is unreliable
A16: 2020-03 | B16: 4232583 | C16: 37884146 | D16: =(B16/B4-1)*100 -> 28.016472 | E16: =(C16/C4-1)*100 -> 28.134035 | F16: =VALUE(MID(A16,6,2)) -> 3 | G16: =IF(AND(ROW()>=14,F16<>2,F16<>3),1,0) -> 0 | H16: =IF(LEFT(A16,4)*1>=2025,1,0) -> 0 | I16: =IF(AND(G16=1,H16=0),1,0) -> 0 | J16: =IF(AND(G16=1,H16=1),1,0) -> 0 | K16: =IF(I16=1,E16,0) -> 0 | L16: =IF(I16=1,D16,0) -> 0 | M16: =IF(J16=1,E16,0) -> 0 | N16: =IF(J16=1,D16,0) -> 0 | O16: =IF(G16=1,"",IF(ROW()<14,"No prior-year base for a y/y comparison","Lunar New Year moves between Feb and Mar, so the y/y comparison is unreliable")) -> Lunar New Year moves between Feb and Mar, so the y/y comparison is unreliable
A17: 2020-04 | B17: 4282426 | C17: 35303249 | D17: =(B17/B5-1)*100 -> 32.941213 | E17: =(C17/C5-1)*100 -> 21.51969 | F17: =VALUE(MID(A17,6,2)) -> 4 | G17: =IF(AND(ROW()>=14,F17<>2,F17<>3),1,0) -> 1 | H17: =IF(LEFT(A17,4)*1>=2025,1,0) -> 0 | I17: =IF(AND(G17=1,H17=0),1,0) -> 1 | J17: =IF(AND(G17=1,H17=1),1,0) -> 0 | K17: =IF(I17=1,E17,0) -> 21.51969 | L17: =IF(I17=1,D17,0) -> 32.941213 | M17: =IF(J17=1,E17,0) -> 0 | N17: =IF(J17=1,D17,0) -> 0 | O17: =IF(G17=1,"",IF(ROW()<14,"No prior-year base for a y/y comparison","Lunar New Year moves between Feb and Mar, so the y/y comparison is unreliable"))
A18: 2020-05 | B18: 4296079 | C18: 35788001 | D18: =(B18/B6-1)*100 -> 23.533825 | E18: =(C18/C6-1)*100 -> 18.825446 | F18: =VALUE(MID(A18,6,2)) -> 5 | G18: =IF(AND(ROW()>=14,F18<>2,F18<>3),1,0) -> 1 | H18: =IF(LEFT(A18,4)*1>=2025,1,0) -> 0 | I18: =IF(AND(G18=1,H18=0),1,0) -> 1 | J18: =IF(AND(G18=1,H18=1),1,0) -> 0 | K18: =IF(I18=1,E18,0) -> 18.825446 | L18: =IF(I18=1,D18,0) -> 23.533825 | M18: =IF(J18=1,E18,0) -> 0 | N18: =IF(J18=1,D18,0) -> 0 | O18: =IF(G18=1,"",IF(ROW()<14,"No prior-year base for a y/y comparison","Lunar New Year moves between Feb and Mar, so the y/y comparison is unreliable"))
A19: 2020-06 | B19: 4254122 | C19: 36457523 | D19: =(B19/B7-1)*100 -> 18.606329 | E19: =(C19/C7-1)*100 -> 15.476729 | F19: =VALUE(MID(A19,6,2)) -> 6 | G19: =IF(AND(ROW()>=14,F19<>2,F19<>3),1,0) -> 1 | H19: =IF(LEFT(A19,4)*1>=2025,1,0) -> 0 | I19: =IF(AND(G19=1,H19=0),1,0) -> 1 | J19: =IF(AND(G19=1,H19=1),1,0) -> 0 | K19: =IF(I19=1,E19,0) -> 15.476729 | L19: =IF(I19=1,D19,0) -> 18.606329 | M19: =IF(J19=1,E19,0) -> 0 | N19: =IF(J19=1,D19,0) -> 0 | O19: =IF(G19=1,"",IF(ROW()<14,"No prior-year base for a y/y comparison","Lunar New Year moves between Feb and Mar, so the y/y comparison is unreliable"))
A20: 2020-07 | B20: 4313667 | C20: 37325504 | D20: =(B20/B8-1)*100 -> 10.703556 | E20: =(C20/C8-1)*100 -> 2.6092443 | F20: =VALUE(MID(A20,6,2)) -> 7 | G20: =IF(AND(ROW()>=14,F20<>2,F20<>3),1,0) -> 1 | H20: =IF(LEFT(A20,4)*1>=2025,1,0) -> 0 | I20: =IF(AND(G20=1,H20=0),1,0) -> 1 | J20: =IF(AND(G20=1,H20=1),1,0) -> 0 | K20: =IF(I20=1,E20,0) -> 2.6092443 | L20: =IF(I20=1,D20,0) -> 10.703556 | M20: =IF(J20=1,E20,0) -> 0 | N20: =IF(J20=1,D20,0) -> 0 | O20: =IF(G20=1,"",IF(ROW()<14,"No prior-year base for a y/y comparison","Lunar New Year moves between Feb and Mar, so the y/y comparison is unreliable"))
A21: 2020-08 | B21: 4468622 | C21: 41944147 | D21: =(B21/B9-1)*100 -> 11.946075 | E21: =(C21/C9-1)*100 -> 4.758155 | F21: =VALUE(MID(A21,6,2)) -> 8 | G21: =IF(AND(ROW()>=14,F21<>2,F21<>3),1,0) -> 1 | H21: =IF(LEFT(A21,4)*1>=2025,1,0) -> 0 | I21: =IF(AND(G21=1,H21=0),1,0) -> 1 | J21: =IF(AND(G21=1,H21=1),1,0) -> 0 | K21: =IF(I21=1,E21,0) -> 4.758155 | L21: =IF(I21=1,D21,0) -> 11.946075 | M21: =IF(J21=1,E21,0) -> 0 | N21: =IF(J21=1,D21,0) -> 0 | O21: =IF(G21=1,"",IF(ROW()<14,"No prior-year base for a y/y comparison","Lunar New Year moves between Feb and Mar, so the y/y comparison is unreliable"))
A22: 2020-09 | B22: 4401098 | C22: 43925748 | D22: =(B22/B10-1)*100 -> 14.648561 | E22: =(C22/C10-1)*100 -> 6.7663924 | F22: =VALUE(MID(A22,6,2)) -> 9 | G22: =IF(AND(ROW()>=14,F22<>2,F22<>3),1,0) -> 1 | H22: =IF(LEFT(A22,4)*1>=2025,1,0) -> 0 | I22: =IF(AND(G22=1,H22=0),1,0) -> 1 | J22: =IF(AND(G22=1,H22=1),1,0) -> 0 | K22: =IF(I22=1,E22,0) -> 6.7663924 | L22: =IF(I22=1,D22,0) -> 14.648561 | M22: =IF(J22=1,E22,0) -> 0 | N22: =IF(J22=1,D22,0) -> 0 | O22: =IF(G22=1,"",IF(ROW()<14,"No prior-year base for a y/y comparison","Lunar New Year moves between Feb and Mar, so the y/y comparison is unreliable"))
A23: 2020-10 | B23: 4291619 | C23: 47914576 | D23: =(B23/B11-1)*100 -> -5.9733683 | E23: =(C23/C11-1)*100 -> 23.54026 | F23: =VALUE(MID(A23,6,2)) -> 10 | G23: =IF(AND(ROW()>=14,F23<>2,F23<>3),1,0) -> 1 | H23: =IF(LEFT(A23,4)*1>=2025,1,0) -> 0 | I23: =IF(AND(G23=1,H23=0),1,0) -> 1 | J23: =IF(AND(G23=1,H23=1),1,0) -> 0 | K23: =IF(I23=1,E23,0) -> 23.54026 | L23: =IF(I23=1,D23,0) -> -5.9733683 | M23: =IF(J23=1,E23,0) -> 0 | N23: =IF(J23=1,D23,0) -> 0 | O23: =IF(G23=1,"",IF(ROW()<14,"No prior-year base for a y/y comparison","Lunar New Year moves between Feb and Mar, so the y/y comparison is unreliable"))
A24: 2020-11 | B24: 4415297 | C24: 50664618 | D24: =(B24/B12-1)*100 -> 12.149936 | E24: =(C24/C12-1)*100 -> 31.745735 | F24: =VALUE(MID(A24,6,2)) -> 11 | G24: =IF(AND(ROW()>=14,F24<>2,F24<>3),1,0) -> 1 | H24: =IF(LEFT(A24,4)*1>=2025,1,0) -> 0 | I24: =IF(AND(G24=1,H24=0),1,0) -> 1 | J24: =IF(AND(G24=1,H24=1),1,0) -> 0 | K24: =IF(I24=1,E24,0) -> 31.745735 | L24: =IF(I24=1,D24,0) -> 12.149936 | M24: =IF(J24=1,E24,0) -> 0 | N24: =IF(J24=1,D24,0) -> 0 | O24: =IF(G24=1,"",IF(ROW()<14,"No prior-year base for a y/y comparison","Lunar New Year moves between Feb and Mar, so the y/y comparison is unreliable"))
A25: 2020-12 | B25: 4542882 | C25: 50298189 | D25: =(B25/B13-1)*100 -> 11.665446 | E25: =(C25/C13-1)*100 -> 29.6961 | F25: =VALUE(MID(A25,6,2)) -> 12 | G25: =IF(AND(ROW()>=14,F25<>2,F25<>3),1,0) -> 1 | H25: =IF(LEFT(A25,4)*1>=2025,1,0) -> 0 | I25: =IF(AND(G25=1,H25=0),1,0) -> 1 | J25: =IF(AND(G25=1,H25=1),1,0) -> 0 | K25: =IF(I25=1,E25,0) -> 29.6961 | L25: =IF(I25=1,D25,0) -> 11.665446 | M25: =IF(J25=1,E25,0) -> 0 | N25: =IF(J25=1,D25,0) -> 0 | O25: =IF(G25=1,"",IF(ROW()<14,"No prior-year base for a y/y comparison","Lunar New Year moves between Feb and Mar, so the y/y comparison is unreliable"))
... A91: 2026-06 | B91: 7132200 | C91: 65783102 | D91: =(B91/B79-1)*100 -> 28.033232 | E91: =(C91/C79-1)*100 -> 32.86128 | F91: =VALUE(MID(A91,6,2)) -> 6 | G91: =IF(AND(ROW()>=14,F91<>2,F91<>3),1,0) -> 1 | H91: =IF(LEFT(A91,4)*1>=2025,1,0) -> 1 | I91: =IF(AND(G91=1,H91=0),1,0) -> 0 | J91: =IF(AND(G91=1,H91=1),1,0) -> 1 | K91: =IF(I91=1,E91,0) -> 0 | L91: =IF(I91=1,D91,0) -> 0 | M91: =IF(J91=1,E91,0) -> 32.86128 | N91: =IF(J91=1,D91,0) -> 28.033232 | O91: =IF(G91=1,"",IF(ROW()<14,"No prior-year base for a y/y comparison","Lunar New Year moves between Feb and Mar, so the y/y comparison is unreliable"))
A93: Blue = raw monthly revenue as filed with MOPS. Everything else is a formula.
A94: Include? is 0 for the first twelve months (no prior-year base) and for every February and March.
A95: Columns K to N zero out observations that fall outside a regime, so the sums on the Regression tab stay simple.

Sheet Regression
A1: Ordinary least squares, computed from raw sums
A2: y = test-house revenue growth (% y/y); x = assembly revenue growth (% y/y)
A4: Sums over included observations | B4: Regime 1 2020–2024 | C4: Regime 2 2025–2026
A5: n (count of observations) | B5: =SUMPRODUCT(Data!$I$2:$I$91) -> 50 | C5: =SUMPRODUCT(Data!$J$2:$J$91) -> 14 | E5: Excludes the first 12 months and every February and March.
A6: Σx | B6: =SUMPRODUCT(Data!$I$2:$I$91,Data!$K$2:$K$91) -> 428.11216 | C6: =SUMPRODUCT(Data!$J$2:$J$91,Data!$M$2:$M$91) -> 173.67322
A7: Σy | B7: =SUMPRODUCT(Data!$I$2:$I$91,Data!$L$2:$L$91) -> 355.62892 | C7: =SUMPRODUCT(Data!$J$2:$J$91,Data!$N$2:$N$91) -> 286.51668
A8: Σx² | B8: =SUMPRODUCT(Data!$I$2:$I$91,Data!$K$2:$K$91,Data!$K$2:$K$91) -> 15094.068 | C8: =SUMPRODUCT(Data!$J$2:$J$91,Data!$M$2:$M$91,Data!$M$2:$M$91) -> 3395.5302
A9: Σxy | B9: =SUMPRODUCT(Data!$I$2:$I$91,Data!$K$2:$K$91,Data!$L$2:$L$91) -> 11306.057 | C9: =SUMPRODUCT(Data!$J$2:$J$91,Data!$M$2:$M$91,Data!$N$2:$N$91) -> 4406.0614
A10: Σy² | B10: =SUMPRODUCT(Data!$I$2:$I$91,Data!$L$2:$L$91,Data!$L$2:$L$91) -> 14626.206 | C10: =SUMPRODUCT(Data!$J$2:$J$91,Data!$N$2:$N$91,Data!$N$2:$N$91) -> 7011.1463
A12: Centred sums of squares
A13: Sxx = Σx² − (Σx)²/n | B13: =B8-B6^2/B5 -> 11428.468 | C13: =C8-C6^2/C5 -> 1241.074
A14: Syy = Σy² − (Σy)²/n | B14: =B10-B7^2/B5 -> 12096.768 | C14: =C10-C7^2/C5 -> 1147.4456
A15: Sxy = Σxy − ΣxΣy/n | B15: =B9-B6*B7/B5 -> 8261.076 | C15: =C9-C6*C7/C5 -> 851.75601
A16: x̄ (mean of x) | B16: =B6/B5 -> 8.5622431 | C16: =C6/C5 -> 12.40523
A17: ȳ (mean of y) | B17: =B7/B5 -> 7.1125784 | C17: =C7/C5 -> 20.465477
A19: Fitted line
A20: Slope b = Sxy / Sxx | B20: =B15/B13 -> 0.72285071 | C20: =C15/C13 -> 0.6863056 | E20: Response of test growth to one point of assembly growth.
A21: Intercept a = ȳ − b·x̄ | B21: =B17-B20*B16 -> 0.92335489 | C21: =C17-C20*C16 -> 11.951699 | E21: Test growth when assembly growth is zero. This is the finding.
A22: R² = Sxy² / (Sxx·Syy) | B22: =B15^2/(B13*B14) -> 0.4936463 | C22: =C15^2/(C13*C14) -> 0.50944893
A23: SSR = Syy − b·Sxy | B23: =B14-B20*B15 -> 6125.2431 | C23: =C14-C20*C15 -> 562.88065 | E23: Residual sum of squares, used for the test below.
A25: Test of the difference between regimes
A26: Degrees of freedom = n₁ + n₂ − 4 | B26: =B5+C5-4 -> 60
A27: Pooled variance s² = (SSR₁+SSR₂)/df | B27: =(B23+C23)/B26 -> 111.46873
A28: Standard error of the intercept gap | B28: =SQRT(B27*((1/B5+B16^2/B13)+(1/C5+C16^2/C13))) -> 4.9727554
A29: Intercept gap a₂ − a₁ | B29: =C21-B21 -> 11.028344 | E29: Percentage points of extra test growth at any level of assembly growth.
A30: t statistic | B30: =B29/B28 -> 2.2177531
A31: p value (two-tailed) | B31: =TDIST(ABS(B30),B26,2) -> 0.030369575 | E31: Classical standard errors. See the note below.
A33: Slope gap b₂ − b₁ | B33: =C20-B20 -> -0.036545116
A34: Standard error of the slope gap | B34: =SQRT(B27*(1/B13+1/C13)) -> 0.31554706
A35: t statistic | B35: =B33/B34 -> -0.1158151
A36: p value (two-tailed) | B36: =TDIST(ABS(B35),B26,2) -> 0.90818583 | E36: Not significant — the slope did not change, only the level.
A38: Note on standard errors. The p value above uses classical OLS standard errors, which is the conservative
A39: reading and the one quoted in the deck. Year-on-year windows overlap, so residuals are autocorrelated;
A40: under heteroskedasticity- and autocorrelation-robust (Newey–West) standard errors the same gap is more
A41: significant, with p between 0.001 and 0.013 depending on the lag length chosen. Robust errors are not
A42: practical in a spreadsheet, so they are computed in the accompanying Python script rather than here.
A44: Robustness. The result also holds without the February and March exclusion: the gap is +9.3 points on the
A45: full 78-month sample. Excluding 2020 for COVID distortion widens it. No specification reverses the sign.

Sheet Chart
A1: Scatter data — included observations only
A2: Every cell below is a live reference to the Data tab. Excluded months are simply not listed, so the plot shows the fitted sample and nothing else.
A4: Regime 1 (2020–2024) | D4: Regime 2 (2025–2026)
A5: x assembly y/y (%) | B5: y test y/y (%) | D5: x assembly y/y (%) | E5: y test y/y (%)
A6: =Data!E14 -> -5.1982387 | B6: =Data!D14 -> 24.926831 | D6: =Data!E74 -> 4.3340191 | E6: =Data!D74 -> -3.9324018
A7: =Data!E17 -> 21.51969 | B7: =Data!D17 -> 32.941213 | D7: =Data!E77 -> 13.94783 | E7: =Data!D77 -> 18.036795
A8: =Data!E18 -> 18.825446 | B8: =Data!D18 -> 23.533825 | D8: =Data!E78 -> 3.2303084 | E8: =Data!D78 -> 11.936226
A9: =Data!E19 -> 15.476729 | B9: =Data!D19 -> 18.606329 | D9: =Data!E79 -> 5.5134677 | E9: =Data!D79 -> 15.305879
A10: =Data!E20 -> 2.6092443 | B10: =Data!D20 -> 10.703556 | D10: =Data!E80 -> -0.10450626 | E10: =Data!D80 -> 13.294285
A11: =Data!E21 -> 4.758155 | B11: =Data!D21 -> 11.946075 | D11: =Data!E81 -> 6.6803003 | E11: =Data!D81 -> 18.79623
A12: =Data!E22 -> 6.7663924 | B12: =Data!D22 -> 14.648561 | D12: =Data!E82 -> 8.9634591 | E12: =Data!D82 -> 22.759103
A13: =Data!E23 -> 23.54026 | B13: =Data!D23 -> -5.9733683 | D13: =Data!E83 -> 6.744322 | E13: =Data!D83 -> 23.976007
A14: =Data!E24 -> 31.745735 | B14: =Data!D24 -> 12.149936 | D14: =Data!E84 -> 11.120122 | E14: =Data!D84 -> 23.117194
A15: =Data!E25 -> 29.6961 | B15: =Data!D25 -> 11.665446 | D15: =Data!E85 -> 11.265366 | E15: =Data!D85 -> 24.354932
A16: =Data!E26 -> 30.348537 | B16: =Data!D26 -> 23.262728 | D16: =Data!E86 -> 21.325771 | E16: =Data!D86 -> 28.437983
A17: =Data!E29 -> 17.081147 | B17: =Data!D29 -> 17.906462 | D17: =Data!E89 -> 19.22274 | E17: =Data!D89 -> 30.293221
A18: =Data!E30 -> 18.103875 | B18: =Data!D30 -> 21.391157 | D18: =Data!E90 -> 28.568741 | E18: =Data!D90 -> 32.107999
A19: =Data!E31 -> 18.839346 | B19: =Data!D31 -> 3.7013043 | D19: =Data!E91 -> 32.86128 | E19: =Data!D91 -> 28.033232
A20: =Data!E32 -> 24.525247 | B20: =Data!D32 -> 29.608359
A21: =Data!E33 -> 20.278355 | B21: =Data!D33 -> 29.104229
A22: =Data!E34 -> 22.332373 | B22: =Data!D34 -> 27.178286
A23: =Data!E35 -> 10.088323 | B23: =Data!D35 -> 29.894313
A24: =Data!E36 -> 19.457905 | B24: =Data!D36 -> 26.128231
A25: =Data!E37 -> 18.622446 | B25: =Data!D37 -> 28.368379
A26: =Data!E38 -> 18.914143 | B26: =Data!D38 -> 19.199789
A27: =Data!E41 -> 17.683368 | B27: =Data!D41 -> 21.769559
A28: =Data!E42 -> 27.282858 | B28: =Data!D42 -> 20.214878
A29: =Data!E43 -> 33.864001 | B29: =Data!D43 -> 41.744228
A30: =Data!E44 -> 25.145246 | B30: =Data!D44 -> 10.247559
A31: =Data!E45 -> 26.476163 | B31: =Data!D45 -> 0.29026655
A32: =Data!E46 -> 24.036588 | B32: =Data!D46 -> 4.1542431
A33: =Data!E47 -> 21.655853 | B33: =Data!D47 -> 3.4848613
A34: =Data!E48 -> -0.68734324 | B34: =Data!D48 -> -0.44622528
A35: =Data!E49 -> -10.937835 | B35: =Data!D49 -> -5.6240766
A36: =Data!E50 -> -7.0873158 | B36: =Data!D50 -> -12.251947
A37: =Data!E53 -> -10.952658 | B37: =Data!D53 -> -20.641549
A38: =Data!E54 -> -14.052161 | B38: =Data!D54 -> -18.295791
A39: =Data!E55 -> -19.442365 | B39: =Data!D55 -> -15.484619
A40: =Data!E56 -> -16.871682 | B40: =Data!D56 -> -12.213113
A41: =Data!E57 -> -18.067145 | B41: =Data!D57 -> -4.0529727
...
